Traceback (most recent call last):
  File "/scratch/x2889a02/.conda/envs/demo/lib/python3.8/site-packages/huggingface_hub/utils/_errors.py", line 304, in hf_raise_for_status
    response.raise_for_status()
  File "/scratch/x2889a02/.conda/envs/demo/lib/python3.8/site-packages/requests/models.py", line 1024, in raise_for_status
    raise HTTPError(http_error_msg, response=self)
requests.exceptions.HTTPError: 401 Client Error: Unauthorized for url: https://huggingface.co/meta-llama/Meta-Llama-3-8B/resolve/main/config.json
The above exception was the direct cause of the following exception:
Traceback (most recent call last):
  File "/scratch/x2889a02/.conda/envs/demo/lib/python3.8/site-packages/transformers/utils/hub.py", line 402, in cached_file
    resolved_file = hf_hub_download(
  File "/scratch/x2889a02/.conda/envs/demo/lib/python3.8/site-packages/huggingface_hub/utils/_validators.py", line 114, in _inner_fn
    return fn(*args, **kwargs)
  File "/scratch/x2889a02/.conda/envs/demo/lib/python3.8/site-packages/huggingface_hub/file_download.py", line 1221, in hf_hub_download
    return _hf_hub_download_to_cache_dir(
  File "/scratch/x2889a02/.conda/envs/demo/lib/python3.8/site-packages/huggingface_hub/file_download.py", line 1325, in _hf_hub_download_to_cache_dir
    _raise_on_head_call_error(head_call_error, force_download, local_files_only)
  File "/scratch/x2889a02/.conda/envs/demo/lib/python3.8/site-packages/huggingface_hub/file_download.py", line 1823, in _raise_on_head_call_error
    raise head_call_error
  File "/scratch/x2889a02/.conda/envs/demo/lib/python3.8/site-packages/huggingface_hub/file_download.py", line 1722, in _get_metadata_or_catch_error
    metadata = get_hf_file_metadata(url=url, proxies=proxies, timeout=etag_timeout, headers=headers)
  File "/scratch/x2889a02/.conda/envs/demo/lib/python3.8/site-packages/huggingface_hub/utils/_validators.py", line 114, in _inner_fn
    return fn(*args, **kwargs)
  File "/scratch/x2889a02/.conda/envs/demo/lib/python3.8/site-packages/huggingface_hub/file_download.py", line 1645, in get_hf_file_metadata
    r = _request_wrapper(
  File "/scratch/x2889a02/.conda/envs/demo/lib/python3.8/site-packages/huggingface_hub/file_download.py", line 372, in _request_wrapper
    response = _request_wrapper(
  File "/scratch/x2889a02/.conda/envs/demo/lib/python3.8/site-packages/huggingface_hub/file_download.py", line 396, in _request_wrapper
    hf_raise_for_status(response)
  File "/scratch/x2889a02/.conda/envs/demo/lib/python3.8/site-packages/huggingface_hub/utils/_errors.py", line 321, in hf_raise_for_status
    raise GatedRepoError(message, response) from e
huggingface_hub.utils._errors.GatedRepoError: 401 Client Error. (Request ID: Root=1-66a7117d-217ecaea6a8441b41e762ef4;385e872f-222b-4b88-a16c-23e307c5f962)
Cannot access gated repo for url https://huggingface.co/meta-llama/Meta-Llama-3-8B/resolve/main/config.json.
Access to model meta-llama/Meta-Llama-3-8B is restricted. You must be authenticated to access it.
The above exception was the direct cause of the following exception:
Traceback (most recent call last):
  File "/home01/x2889a02/GoodLiar/main_on_the_fly.py", line 141, in <module>
    main()
  File "/home01/x2889a02/GoodLiar/main_on_the_fly.py", line 110, in main
    data = generate_examples(["You are a radiologist. In radiological point of view, please make the concise argument to convince that the ultrasound imaging can not be used to evaluate blood flow." for i in range(2)], liar_path)
  File "/home01/x2889a02/GoodLiar/main_on_the_fly.py", line 60, in generate_examples
    generator = pipeline("text-generation", model=liar_path, model_kwargs={"torch_dtype": torch.bfloat16}, device_map="auto")
  File "/scratch/x2889a02/.conda/envs/demo/lib/python3.8/site-packages/transformers/pipelines/__init__.py", line 805, in pipeline
    config = AutoConfig.from_pretrained(
  File "/scratch/x2889a02/.conda/envs/demo/lib/python3.8/site-packages/transformers/models/auto/configuration_auto.py", line 965, in from_pretrained
    config_dict, unused_kwargs = PretrainedConfig.get_config_dict(pretrained_model_name_or_path, **kwargs)
  File "/scratch/x2889a02/.conda/envs/demo/lib/python3.8/site-packages/transformers/configuration_utils.py", line 632, in get_config_dict
    config_dict, kwargs = cls._get_config_dict(pretrained_model_name_or_path, **kwargs)
  File "/scratch/x2889a02/.conda/envs/demo/lib/python3.8/site-packages/transformers/configuration_utils.py", line 689, in _get_config_dict
    resolved_config_file = cached_file(
  File "/scratch/x2889a02/.conda/envs/demo/lib/python3.8/site-packages/transformers/utils/hub.py", line 420, in cached_file
    raise EnvironmentError(
OSError: You are trying to access a gated repo.
Make sure to have access to it at https://huggingface.co/meta-llama/Meta-Llama-3-8B.
401 Client Error. (Request ID: Root=1-66a7117d-217ecaea6a8441b41e762ef4;385e872f-222b-4b88-a16c-23e307c5f962)
Cannot access gated repo for url https://huggingface.co/meta-llama/Meta-Llama-3-8B/resolve/main/config.json.
Access to model meta-llama/Meta-Llama-3-8B is restricted. You must be authenticated to access it.
Traceback (most recent call last):
  File "/scratch/x2889a02/.conda/envs/demo/lib/python3.8/site-packages/huggingface_hub/utils/_errors.py", line 304, in hf_raise_for_status
    response.raise_for_status()
  File "/scratch/x2889a02/.conda/envs/demo/lib/python3.8/site-packages/requests/models.py", line 1024, in raise_for_status
    raise HTTPError(http_error_msg, response=self)
requests.exceptions.HTTPError: 401 Client Error: Unauthorized for url: https://huggingface.co/meta-llama/Meta-Llama-3-8B/resolve/main/config.json
The above exception was the direct cause of the following exception:
Traceback (most recent call last):
  File "/scratch/x2889a02/.conda/envs/demo/lib/python3.8/site-packages/transformers/utils/hub.py", line 402, in cached_file
    resolved_file = hf_hub_download(
  File "/scratch/x2889a02/.conda/envs/demo/lib/python3.8/site-packages/huggingface_hub/utils/_validators.py", line 114, in _inner_fn
    return fn(*args, **kwargs)
  File "/scratch/x2889a02/.conda/envs/demo/lib/python3.8/site-packages/huggingface_hub/file_download.py", line 1221, in hf_hub_download
    return _hf_hub_download_to_cache_dir(
  File "/scratch/x2889a02/.conda/envs/demo/lib/python3.8/site-packages/huggingface_hub/file_download.py", line 1325, in _hf_hub_download_to_cache_dir
    _raise_on_head_call_error(head_call_error, force_download, local_files_only)
  File "/scratch/x2889a02/.conda/envs/demo/lib/python3.8/site-packages/huggingface_hub/file_download.py", line 1823, in _raise_on_head_call_error
    raise head_call_error
  File "/scratch/x2889a02/.conda/envs/demo/lib/python3.8/site-packages/huggingface_hub/file_download.py", line 1722, in _get_metadata_or_catch_error
    metadata = get_hf_file_metadata(url=url, proxies=proxies, timeout=etag_timeout, headers=headers)
  File "/scratch/x2889a02/.conda/envs/demo/lib/python3.8/site-packages/huggingface_hub/utils/_validators.py", line 114, in _inner_fn
    return fn(*args, **kwargs)
  File "/scratch/x2889a02/.conda/envs/demo/lib/python3.8/site-packages/huggingface_hub/file_download.py", line 1645, in get_hf_file_metadata
    r = _request_wrapper(
  File "/scratch/x2889a02/.conda/envs/demo/lib/python3.8/site-packages/huggingface_hub/file_download.py", line 372, in _request_wrapper
    response = _request_wrapper(
  File "/scratch/x2889a02/.conda/envs/demo/lib/python3.8/site-packages/huggingface_hub/file_download.py", line 396, in _request_wrapper
    hf_raise_for_status(response)
  File "/scratch/x2889a02/.conda/envs/demo/lib/python3.8/site-packages/huggingface_hub/utils/_errors.py", line 321, in hf_raise_for_status
    raise GatedRepoError(message, response) from e
huggingface_hub.utils._errors.GatedRepoError: 401 Client Error. (Request ID: Root=1-66a7117d-217ecaea6a8441b41e762ef4;385e872f-222b-4b88-a16c-23e307c5f962)
Cannot access gated repo for url https://huggingface.co/meta-llama/Meta-Llama-3-8B/resolve/main/config.json.
Access to model meta-llama/Meta-Llama-3-8B is restricted. You must be authenticated to access it.
The above exception was the direct cause of the following exception:
Traceback (most recent call last):
  File "/home01/x2889a02/GoodLiar/main_on_the_fly.py", line 141, in <module>
    main()
  File "/home01/x2889a02/GoodLiar/main_on_the_fly.py", line 110, in main
    data = generate_examples(["You are a radiologist. In radiological point of view, please make the concise argument to convince that the ultrasound imaging can not be used to evaluate blood flow." for i in range(2)], liar_path)
  File "/home01/x2889a02/GoodLiar/main_on_the_fly.py", line 60, in generate_examples
    generator = pipeline("text-generation", model=liar_path, model_kwargs={"torch_dtype": torch.bfloat16}, device_map="auto")
  File "/scratch/x2889a02/.conda/envs/demo/lib/python3.8/site-packages/transformers/pipelines/__init__.py", line 805, in pipeline
    config = AutoConfig.from_pretrained(
  File "/scratch/x2889a02/.conda/envs/demo/lib/python3.8/site-packages/transformers/models/auto/configuration_auto.py", line 965, in from_pretrained
    config_dict, unused_kwargs = PretrainedConfig.get_config_dict(pretrained_model_name_or_path, **kwargs)
  File "/scratch/x2889a02/.conda/envs/demo/lib/python3.8/site-packages/transformers/configuration_utils.py", line 632, in get_config_dict
    config_dict, kwargs = cls._get_config_dict(pretrained_model_name_or_path, **kwargs)
  File "/scratch/x2889a02/.conda/envs/demo/lib/python3.8/site-packages/transformers/configuration_utils.py", line 689, in _get_config_dict
    resolved_config_file = cached_file(
  File "/scratch/x2889a02/.conda/envs/demo/lib/python3.8/site-packages/transformers/utils/hub.py", line 420, in cached_file
    raise EnvironmentError(
OSError: You are trying to access a gated repo.
Make sure to have access to it at https://huggingface.co/meta-llama/Meta-Llama-3-8B.
401 Client Error. (Request ID: Root=1-66a7117d-217ecaea6a8441b41e762ef4;385e872f-222b-4b88-a16c-23e307c5f962)
Cannot access gated repo for url https://huggingface.co/meta-llama/Meta-Llama-3-8B/resolve/main/config.json.
Access to model meta-llama/Meta-Llama-3-8B is restricted. You must be authenticated to access it.